Workbook

Sheet ListRelacion impactos-indicador
A1: Nº | B1: Tipo de impacto | C1: Modos de fallo / Modos de parada | D1: Variable | E1: Activo físico u Operacional | F1: Tipo activo/servicio | G1: UM | H1: Umbral General | I1: Graneles Líquidos | J1: Graneles Sólidos | K1: Carga contenerizada | L1: Ro-ro y resto de mercancía general no contenerizada | M1: Pasajeros | N1: Pesquero | O1: Náutico-deportivo | P1: Puerto-ciudad
A2: 1 | B2: ELO | C2: Exceso de Oleaje | D2: Oleaje | E2: Zona de fondeo y espera exterior | F2: Activo físico | G2: =IF(C2="","",IFERROR(IF(INDEX(UnidadMedida!$B$1:$B$30,MATCH(C2,UnidadMedida!$A$1:$A$30,0))="","",INDEX(UnidadMedida!$B$1:$B$30,MATCH(C2,UnidadMedida!$A$1:$A$30,0))),"")) -> m | H2: 2.5 | N2: 5 | O2: 5
A3: 2 | B3: ELO | C3: Exceso de Viento | D3: Viento | E3: Zona de fondeo y espera exterior | F3: Activo físico | G3: =IF(C3="","",IFERROR(IF(INDEX(UnidadMedida!$B$1:$B$30,MATCH(C3,UnidadMedida!$A$1:$A$30,0))="","",INDEX(UnidadMedida!$B$1:$B$30,MATCH(C3,UnidadMedida!$A$1:$A$30,0))),"")) -> m/s | H3: 24
A4: 3 | B4: ELO | C4: Exceso de Oleaje | D4: Oleaje | E4: Bocana | F4: Activo físico | G4: =IF(C4="","",IFERROR(IF(INDEX(UnidadMedida!$B$1:$B$30,MATCH(C4,UnidadMedida!$A$1:$A$30,0))="","",INDEX(UnidadMedida!$B$1:$B$30,MATCH(C4,UnidadMedida!$A$1:$A$30,0))),"")) -> m | H4: 2
A5: 4 | B5: ELO | C5: Exceso de Viento | D5: Viento | E5: Bocana | F5: Activo físico | G5: =IF(C5="","",IFERROR(IF(INDEX(UnidadMedida!$B$1:$B$30,MATCH(C5,UnidadMedida!$A$1:$A$30,0))="","",INDEX(UnidadMedida!$B$1:$B$30,MATCH(C5,UnidadMedida!$A$1:$A$30,0))),"")) -> m/s | H5: 10 | N5: 16 | O5: 16
A6: 5 | B6: ELO | C6: Exceso de Corriente | D6: Corriente | E6: Bocana | F6: Activo físico | G6: =IF(C6="","",IFERROR(IF(INDEX(UnidadMedida!$B$1:$B$30,MATCH(C6,UnidadMedida!$A$1:$A$30,0))="","",INDEX(UnidadMedida!$B$1:$B$30,MATCH(C6,UnidadMedida!$A$1:$A$30,0))),"")) -> m/s | H6: 0.5 | N6: 2 | O6: 2
A7: 6 | B7: ELO | C7: Visibilidad reducida | D7: Visibilidad | E7: Bocana | F7: Activo físico | G7: =IF(C7="","",IFERROR(IF(INDEX(UnidadMedida!$B$1:$B$30,MATCH(C7,UnidadMedida!$A$1:$A$30,0))="","",INDEX(UnidadMedida!$B$1:$B$30,MATCH(C7,UnidadMedida!$A$1:$A$30,0))),"")) -> km | H7: 1
A8: 7 | B8: ELO | C8: Exceso de Oleaje | D8: Oleaje | E8: Canal de acceso / navegación | F8: Activo físico | G8: =IF(C8="","",IFERROR(IF(INDEX(UnidadMedida!$B$1:$B$30,MATCH(C8,UnidadMedida!$A$1:$A$30,0))="","",INDEX(UnidadMedida!$B$1:$B$30,MATCH(C8,UnidadMedida!$A$1:$A$30,0))),"")) -> m | H8: 2.5
A9: 8 | B9: ELO | C9: Exceso de Viento | D9: Viento | E9: Canal de acceso / navegación | F9: Activo físico | G9: =IF(C9="","",IFERROR(IF(INDEX(UnidadMedida!$B$1:$B$30,MATCH(C9,UnidadMedida!$A$1:$A$30,0))="","",INDEX(UnidadMedida!$B$1:$B$30,MATCH(C9,UnidadMedida!$A$1:$A$30,0))),"")) -> m/s | H9: 17
A10: 9 | B10: ELO | C10: Exceso de Corriente | D10: Corriente | E10: Canal de acceso / navegación | F10: Activo físico | G10: =IF(C10="","",IFERROR(IF(INDEX(UnidadMedida!$B$1:$B$30,MATCH(C10,UnidadMedida!$A$1:$A$30,0))="","",INDEX(UnidadMedida!$B$1:$B$30,MATCH(C10,UnidadMedida!$A$1:$A$30,0))),"")) -> m/s | H10: 2
A11: 10 | B11: ELO | C11: Visibilidad reducida | D11: Visibilidad | E11: Canal de acceso / navegación | F11: Activo físico | G11: =IF(C11="","",IFERROR(IF(INDEX(UnidadMedida!$B$1:$B$30,MATCH(C11,UnidadMedida!$A$1:$A$30,0))="","",INDEX(UnidadMedida!$B$1:$B$30,MATCH(C11,UnidadMedida!$A$1:$A$30,0))),"")) -> km | H11: 1
A12: 11 | B12: ELO | C12: Exceso de Oleaje | D12: Oleaje | E12: Dársenas (zona de permanencia) | F12: Activo físico | G12: =IF(C12="","",IFERROR(IF(INDEX(UnidadMedida!$B$1:$B$30,MATCH(C12,UnidadMedida!$A$1:$A$30,0))="","",INDEX(UnidadMedida!$B$1:$B$30,MATCH(C12,UnidadMedida!$A$1:$A$30,0))),"")) -> m | H12: 2
A13: 12 | B13: ELO | C13: Exceso de Viento | D13: Viento | E13: Dársenas (zona de permanencia) | F13: Activo físico | G13: =IF(C13="","",IFERROR(IF(INDEX(UnidadMedida!$B$1:$B$30,MATCH(C13,UnidadMedida!$A$1:$A$30,0))="","",INDEX(UnidadMedida!$B$1:$B$30,MATCH(C13,UnidadMedida!$A$1:$A$30,0))),"")) -> m/s | H13: 10
A14: 13 | B14: ELO | C14: Exceso de Corriente | D14: Corriente | E14: Dársenas (zona de permanencia) | F14: Activo físico | G14: =IF(C14="","",IFERROR(IF(INDEX(UnidadMedida!$B$1:$B$30,MATCH(C14,UnidadMedida!$A$1:$A$30,0))="","",INDEX(UnidadMedida!$B$1:$B$30,MATCH(C14,UnidadMedida!$A$1:$A$30,0))),"")) -> m/s | H14: 0.5
A15: 14 | B15: ELO | C15: Visibilidad reducida | D15: Visibilidad | E15: Dársenas (zona de permanencia) | F15: Activo físico | G15: =IF(C15="","",IFERROR(IF(INDEX(UnidadMedida!$B$1:$B$30,MATCH(C15,UnidadMedida!$A$1:$A$30,0))="","",INDEX(UnidadMedida!$B$1:$B$30,MATCH(C15,UnidadMedida!$A$1:$A$30,0))),"")) -> km | H15: 1
A16: 15 | B16: ELO | C16: Exceso de Oleaje | D16: Oleaje | E16: Dársenas (zona de maniobra y reviro) | F16: Activo físico | G16: =IF(C16="","",IFERROR(IF(INDEX(UnidadMedida!$B$1:$B$30,MATCH(C16,UnidadMedida!$A$1:$A$30,0))="","",INDEX(UnidadMedida!$B$1:$B$30,MATCH(C16,UnidadMedida!$A$1:$A$30,0))),"")) -> m | H16: 1
A17: 16 | B17: ELO | C17: Exceso de Viento | D17: Viento | E17: Dársenas (zona de maniobra y reviro) | F17: Activo físico | G17: =IF(C17="","",IFERROR(IF(INDEX(UnidadMedida!$B$1:$B$30,MATCH(C17,UnidadMedida!$A$1:$A$30,0))="","",INDEX(UnidadMedida!$B$1:$B$30,MATCH(C17,UnidadMedida!$A$1:$A$30,0))),"")) -> m/s | H17: 10
A18: 17 | B18: ELO | C18: Exceso de Corriente | D18: Corriente | E18: Dársenas (zona de maniobra y reviro) | F18: Activo físico | G18: =IF(C18="","",IFERROR(IF(INDEX(UnidadMedida!$B$1:$B$30,MATCH(C18,UnidadMedida!$A$1:$A$30,0))="","",INDEX(UnidadMedida!$B$1:$B$30,MATCH(C18,UnidadMedida!$A$1:$A$30,0))),"")) -> m/s | H18: 0.5
... A28: 27 | B28: ELO | C28: Exceso de Viento | D28: Viento | E28: Operaciones a flote (bunkering...) | F28: Operacional (servicios) | G28: =IF(C28="","",IFERROR(IF(INDEX(UnidadMedida!$B$1:$B$30,MATCH(C28,UnidadMedida!$A$1:$A$30,0))="","",INDEX(UnidadMedida!$B$1:$B$30,MATCH(C28,UnidadMedida!$A$1:$A$30,0))),"")) -> m/s | H28: 17
A29: 28 | B29: ELO | C29: Rebase sobre obras de abrigo por acción del oleaje | D29: Oleaje | E29: Dique en talud (con espaldón o sin espaldón) | F29: Activo físico | G29: =IF(C29="","",IFERROR(IF(INDEX(UnidadMedida!$B$1:$B$30,MATCH(C29,UnidadMedida!$A$1:$A$30,0))="","",INDEX(UnidadMedida!$B$1:$B$30,MATCH(C29,UnidadMedida!$A$1:$A$30,0))),"")) -> m/s/m
A30: 29 | B30: ELO | C30: Carga hidráulica sobre las piezas de obras de abrigo (desplazamiento de las piezas del tronco, morro) | D30: Oleaje, Nivel del mar | E30: Dique en talud (con espaldón o sin espaldón) | F30: Activo físico | G30: =IF(C30="","",IFERROR(IF(INDEX(UnidadMedida!$B$1:$B$30,MATCH(C30,UnidadMedida!$A$1:$A$30,0))="","",INDEX(UnidadMedida!$B$1:$B$30,MATCH(C30,UnidadMedida!$A$1:$A$30,0))),""))
A31: 30 | B31: ELO | C31: Carga hidráulica sobre las piezas de obras de abrigo (erosión berma de pie) | D31: Oleaje, Nivel del mar | E31: Dique en talud (con espaldón o sin espaldón) | F31: Activo físico | G31: =IF(C31="","",IFERROR(IF(INDEX(UnidadMedida!$B$1:$B$30,MATCH(C31,UnidadMedida!$A$1:$A$30,0))="","",INDEX(UnidadMedida!$B$1:$B$30,MATCH(C31,UnidadMedida!$A$1:$A$30,0))),""))
A32: 31 | B32: ELO | C32: Carga hidráulica sobre las piezas de obras de abrigo (desplazamiento o vuelco del espaldón) | D32: Oleaje, Nivel del mar | E32: Dique en talud (con espaldón o sin espaldón) | F32: Activo físico | G32: =IF(C32="","",IFERROR(IF(INDEX(UnidadMedida!$B$1:$B$30,MATCH(C32,UnidadMedida!$A$1:$A$30,0))="","",INDEX(UnidadMedida!$B$1:$B$30,MATCH(C32,UnidadMedida!$A$1:$A$30,0))),""))
A33: 32 | B33: ELO | C33: Rebase sobre obras de abrigo por acción del oleaje | D33: Oleaje | E33: Dique vertical | F33: Activo físico | G33: =IF(C33="","",IFERROR(IF(INDEX(UnidadMedida!$B$1:$B$30,MATCH(C33,UnidadMedida!$A$1:$A$30,0))="","",INDEX(UnidadMedida!$B$1:$B$30,MATCH(C33,UnidadMedida!$A$1:$A$30,0))),"")) -> m/s/m
A34: 33 | B34: ELO | C34: Carga hidráulica sobre las piezas de obras de abrigo (desplazamiento de las piezas del tronco, morro o berma) | D34: Oleaje, Nivel del mar | E34: Dique vertical | F34: Activo físico | G34: =IF(C34="","",IFERROR(IF(INDEX(UnidadMedida!$B$1:$B$30,MATCH(C34,UnidadMedida!$A$1:$A$30,0))="","",INDEX(UnidadMedida!$B$1:$B$30,MATCH(C34,UnidadMedida!$A$1:$A$30,0))),""))
A35: 34 | B35: ELO | C35: Carga hidráulica sobre las piezas de obras de abrigo (erosión de la banqueta) | D35: Oleaje, Nivel del mar | E35: Dique vertical | F35: Activo físico | G35: =IF(C35="","",IFERROR(IF(INDEX(UnidadMedida!$B$1:$B$30,MATCH(C35,UnidadMedida!$A$1:$A$30,0))="","",INDEX(UnidadMedida!$B$1:$B$30,MATCH(C35,UnidadMedida!$A$1:$A$30,0))),""))
A36: 35 | B36: ELO | C36: Carga hidráulica sobre las piezas de obras de abrigo (desplazamiento o vuelco del espaldón) | D36: Oleaje, Nivel del mar | E36: Dique vertical | F36: Activo físico | G36: =IF(C36="","",IFERROR(IF(INDEX(UnidadMedida!$B$1:$B$30,MATCH(C36,UnidadMedida!$A$1:$A$30,0))="","",INDEX(UnidadMedida!$B$1:$B$30,MATCH(C36,UnidadMedida!$A$1:$A$30,0))),""))
A37: 36 | B37: ELO | C37: Falta de francobordo | D37: Nivel del mar | E37: Muelle | F37: Activo físico | G37: =IF(C37="","",IFERROR(IF(INDEX(UnidadMedida!$B$1:$B$30,MATCH(C37,UnidadMedida!$A$1:$A$30,0))="","",INDEX(UnidadMedida!$B$1:$B$30,MATCH(C37,UnidadMedida!$A$1:$A$30,0))),"")) -> m | H37: 0.5
A38: 37 | B38: ELO | C38: Exceso de Oleaje | D38: Oleaje | E38: Muelle | F38: Activo físico | G38: =IF(C38="","",IFERROR(IF(INDEX(UnidadMedida!$B$1:$B$30,MATCH(C38,UnidadMedida!$A$1:$A$30,0))="","",INDEX(UnidadMedida!$B$1:$B$30,MATCH(C38,UnidadMedida!$A$1:$A$30,0))),"")) -> m | H38: 1.5 | I38: 1.5 | J38: 1.5 | L38: 0.3 | M38: 0.3 | N38: 0.4 | O38: 0.4
A39: 38 | B39: ELO | C39: Falta de Calado | D39: Nivel del mar | E39: Muelle | F39: Activo físico | G39: =IF(C39="","",IFERROR(IF(INDEX(UnidadMedida!$B$1:$B$30,MATCH(C39,UnidadMedida!$A$1:$A$30,0))="","",INDEX(UnidadMedida!$B$1:$B$30,MATCH(C39,UnidadMedida!$A$1:$A$30,0))),"")) -> m | H39: 1.05*Dc+0.75
A40: 39 | B40: ELO | C40: Falta de francobordo | D40: Nivel del mar | E40: Pantalán | F40: Activo físico | G40: =IF(C40="","",IFERROR(IF(INDEX(UnidadMedida!$B$1:$B$30,MATCH(C40,UnidadMedida!$A$1:$A$30,0))="","",INDEX(UnidadMedida!$B$1:$B$30,MATCH(C40,UnidadMedida!$A$1:$A$30,0))),"")) -> m | H40: 0.5
A41: 40 | B41: ELO | C41: Exceso de Oleaje | D41: Oleaje | E41: Pantalán | F41: Activo físico | G41: =IF(C41="","",IFERROR(IF(INDEX(UnidadMedida!$B$1:$B$30,MATCH(C41,UnidadMedida!$A$1:$A$30,0))="","",INDEX(UnidadMedida!$B$1:$B$30,MATCH(C41,UnidadMedida!$A$1:$A$30,0))),"")) -> m | H41: 1.5 | I41: 1.5 | J41: 1.5 | L41: 0.3 | M41: 0.3 | N41: 0.4 | O41: 0.4
A42: 41 | B42: ELO | C42: Falta de Calado | D42: Nivel del mar | E42: Pantalán | F42: Activo físico | G42: =IF(C42="","",IFERROR(IF(INDEX(UnidadMedida!$B$1:$B$30,MATCH(C42,UnidadMedida!$A$1:$A$30,0))="","",INDEX(UnidadMedida!$B$1:$B$30,MATCH(C42,UnidadMedida!$A$1:$A$30,0))),"")) -> m | H42: 1.05*Dc+0.75
A43: 42 | B43: ELO | C43: Falta de francobordo | D43: Nivel del mar | E43: Duque de alba | F43: Activo físico | G43: =IF(C43="","",IFERROR(IF(INDEX(UnidadMedida!$B$1:$B$30,MATCH(C43,UnidadMedida!$A$1:$A$30,0))="","",INDEX(UnidadMedida!$B$1:$B$30,MATCH(C43,UnidadMedida!$A$1:$A$30,0))),"")) -> m | H43: 0.5
A44: 43 | B44: ELO | C44: Exceso de Oleaje | D44: Oleaje | E44: Duque de alba | F44: Activo físico | G44: =IF(C44="","",IFERROR(IF(INDEX(UnidadMedida!$B$1:$B$30,MATCH(C44,UnidadMedida!$A$1:$A$30,0))="","",INDEX(UnidadMedida!$B$1:$B$30,MATCH(C44,UnidadMedida!$A$1:$A$30,0))),"")) -> m | H44: 1.5 | I44: 1.5 | J44: 1.5 | L44: 0.3 | M44: 0.3 | N44: 0.4 | O44: 0.4
A45: 44 | B45: ELO | C45: Falta de Calado | D45: Nivel del mar | E45: Duque de alba | F45: Activo físico | G45: =IF(C45="","",IFERROR(IF(INDEX(UnidadMedida!$B$1:$B$30,MATCH(C45,UnidadMedida!$A$1:$A$30,0))="","",INDEX(UnidadMedida!$B$1:$B$30,MATCH(C45,UnidadMedida!$A$1:$A$30,0))),"")) -> m | H45: 1.05*Dc+0.75
A46: 45 | B46: ELO | C46: Exceso de Oleaje | D46: Oleaje | E46: Boya / monoboya | F46: Activo físico | G46: =IF(C46="","",IFERROR(IF(INDEX(UnidadMedida!$B$1:$B$30,MATCH(C46,UnidadMedida!$A$1:$A$30,0))="","",INDEX(UnidadMedida!$B$1:$B$30,MATCH(C46,UnidadMedida!$A$1:$A$30,0))),"")) -> m | H46: 1.5 | I46: 1.5 | J46: 1.5 | L46: 0.3 | M46: 0.3 | N46: 0.4 | O46: 0.4
A47: 46 | B47: ELO | C47: Falta de Calado | D47: Nivel del mar | E47: Boya / monoboya | F47: Activo físico | G47: =IF(C47="","",IFERROR(IF(INDEX(UnidadMedida!$B$1:$B$30,MATCH(C47,UnidadMedida!$A$1:$A$30,0))="","",INDEX(UnidadMedida!$B$1:$B$30,MATCH(C47,UnidadMedida!$A$1:$A$30,0))),"")) -> m | H47: 1.05*Dc+0.75
A48: 47 | B48: ELO | C48: Falta de francobordo | D48: Nivel del mar | E48: Rampa Ro-Ro | F48: Activo físico | G48: =IF(C48="","",IFERROR(IF(INDEX(UnidadMedida!$B$1:$B$30,MATCH(C48,UnidadMedida!$A$1:$A$30,0))="","",INDEX(UnidadMedida!$B$1:$B$30,MATCH(C48,UnidadMedida!$A$1:$A$30,0))),"")) -> m | H48: 0.5
A49: 48 | B49: ELO | C49: Exceso de Oleaje | D49: Oleaje | E49: Rampa Ro-Ro | F49: Activo físico | G49: =IF(C49="","",IFERROR(IF(INDEX(UnidadMedida!$B$1:$B$30,MATCH(C49,UnidadMedida!$A$1:$A$30,0))="","",INDEX(UnidadMedida!$B$1:$B$30,MATCH(C49,UnidadMedida!$A$1:$A$30,0))),"")) -> m | H49: 1.5 | I49: 1.5 | J49: 1.5 | L49: 0.3 | M49: 0.3 | N49: 0.4 | O49: 0.4
...

Sheet UnidadMedida
A1: Fallo | B1: UM
A2: Exceso de Oleaje | B2: m
A3: Exceso de Viento | B3: m/s
A4: Exceso de Corriente | B4: m/s
A5: Visibilidad reducida | B5: km
A6: Rebase sobre obras de abrigo por acción del oleaje | B6: m/s/m
A7: Carga hidráulica sobre las piezas de obras de abrigo (desplazamiento de las piezas del tronco, morro)
A8: Carga hidráulica sobre las piezas de obras de abrigo (erosión berma de pie)
A9: Carga hidráulica sobre las piezas de obras de abrigo (desplazamiento o vuelco del espaldón)
A10: Carga hidráulica sobre las piezas de obras de abrigo (desplazamiento de las piezas del tronco, morro o berma)
A11: Carga hidráulica sobre las piezas de obras de abrigo (erosión de la banqueta)
A12: Falta de francobordo | B12: m
A13: Falta de Calado | B13: m
A14: Asociado a los EL de la obra de amarre y atraque (% de la perdida por parada)
A15: Inundación | B15: m
A16: Exceso de precipitación | B16: mm
A17: Por temperatura extrema | B17: °C
A18: Deterioro de la señalización/balizamiento
A19: Por deterioro debido a temperatura del aire excesiva
A20: Deterioro debido a inundación
A21: Por daños en infraestructuras debido a temperatura del aire excesiva
A22: Daño debido a viento
A23: Incremento de costes energéticos
A24: Por temperatura del aire excesiva | B24: °C
A25: Daño estructural debido a inundación
A26: Por daños en infraestructura debido a Temperatura del aire excesiva
A27: Por viento | B27: m/s
A28: Fallo de la señalización/balizamiento
A29: Carga hidráulica sobre las obras de amarre
A30: Asociado a los EL de la obra de amarre y atraque (% del daño)

Sheet CONTAR
A1: Compuestos | B1: Rebase | C1: Asociados | D1: Temperatura | E1: Inundación | F1: Precipitación | G1: Agitación-Oleaje | H1: Viento | I1: Corriente | J1: Visibilidad | K1: Calado | L1: Francobordo | N1: ListRelacion impactos-indicador
A2: =COUNTA(INDIRECT(A1&"!A2#")) -> 18 | B2: =COUNTA(INDIRECT(B1&"!A2#")) -> 4 | C2: =COUNTA(INDIRECT(C1&"!A2#")) -> 3 | D2: =COUNTA(INDIRECT(D1&"!A2#")) -> 12 | E2: =COUNTA(INDIRECT(E1&"!A2#")) -> 1 | F2: =COUNTA(INDIRECT(F1&"!A2#")) -> 2 | G2: =COUNTA(_xlfn.ANCHORARRAY('Agitación-Oleaje'!B2)) -> 13 | H2: =COUNTA(INDIRECT(H1&"!A2#")) -> 43 | I2: =COUNTA(INDIRECT(I1&"!A2#")) -> 4 | J2: =COUNTA(INDIRECT(J1&"!A2#")) -> 10 | K2: =COUNTA(INDIRECT(K1&"!A2#")) -> 15 | L2: =COUNTA(INDIRECT(L1&"!A2#")) -> 4 | M2: =+SUM(A2:L2) -> 129 | N2: =+COUNT('ListRelacion impactos-indicador'!A2:A182) -> 181 | O2: =+N2-M2 -> 52
A3: {=_xlfn._xlws.FILTER(INDIRECT("'"&A1&"'!A2:A176"),INDIRECT("'"&A1&"'!A2:A176")<>"","")} -> Compuestos | B3: {=_xlfn._xlws.FILTER(INDIRECT("'"&B1&"'!A2:A176"),INDIRECT("'"&B1&"'!A2:A176")<>"","")} -> Rebase | C3: {=_xlfn._xlws.FILTER(INDIRECT("'"&C1&"'!A2:A176"),INDIRECT("'"&C1&"'!A2:A176")<>"","")} -> Asociados | D3: {=_xlfn._xlws.FILTER(INDIRECT("'"&D1&"'!A2:A176"),INDIRECT("'"&D1&"'!A2:A176")<>"","")} -> Temperatura | E3: {=_xlfn._xlws.FILTER(INDIRECT("'"&E1&"'!A2:A176"),INDIRECT("'"&E1&"'!A2:A176")<>"","")} -> #REF! | F3: {=_xlfn._xlws.FILTER(INDIRECT("'"&F1&"'!A2:A176"),INDIRECT("'"&F1&"'!A2:A176")<>"","")} -> Precipitación | G3: {=_xlfn._xlws.FILTER(INDIRECT("'"&G1&"'!A2:A176"),INDIRECT("'"&G1&"'!A2:A176")<>"","")} -> Agitación-Oleaje | H3: {=_xlfn._xlws.FILTER(INDIRECT("'"&H1&"'!A2:A176"),INDIRECT("'"&H1&"'!A2:A176")<>"","")} -> Viento | ... L3: {=_xlfn._xlws.FILTER(INDIRECT("'"&L1&"'!A2:A176"),INDIRECT("'"&L1&"'!A2:A176")<>"","")} -> Francobordo | M3: {=_xlfn._xlws.FILTER(_xlfn.SEQUENCE(175),ISERROR(MATCH(_xlfn.SEQUENCE(175),A3:L55,0)))} -> 1 | N3: {=_xlfn._xlws.FILTER(INDIRECT("'"&N1&"'!A2:A176"),INDIRECT("'"&N1&"'!A2:A176")<>"","")} -> 1 | O3: =+IF(M3=N3,"","E")
A4: Compuestos | B4: Rebase | C4: Asociados | D4: Temperatura | F4: Precipitación | G4: Agitación-Oleaje | H4: Viento | I4: Corriente | J4: Visibilidad | K4: Calado | L4: Francobordo | M4: 2 | N4: 2 | O4: =+IF(M4=N4,"","E")
A5: Compuestos | B5: Rebase | C5: Asociados | D5: Temperatura | G5: Agitación-Oleaje | H5: Viento | I5: Corriente | J5: Visibilidad | K5: Calado | L5: Francobordo | M5: 3 | N5: 3 | O5: =+IF(M5=N5,"","E")
A6: Compuestos | B6: Rebase | D6: Temperatura | G6: Agitación-Oleaje | H6: Viento | I6: Corriente | J6: Visibilidad | K6: Calado | L6: Francobordo | M6: 4 | N6: 4 | O6: =+IF(M6=N6,"","E")
A7: Compuestos | D7: Temperatura | G7: Agitación-Oleaje | H7: Viento | J7: Visibilidad | K7: Calado | M7: 5 | N7: 5 | O7: =+IF(M7=N7,"","E")
A8: Compuestos | D8: Temperatura | G8: Agitación-Oleaje | H8: Viento | J8: Visibilidad | K8: Calado | M8: 6 | N8: 6 | O8: =+IF(M8=N8,"","E")
A9: Compuestos | D9: Temperatura | G9: Agitación-Oleaje | H9: Viento | J9: Visibilidad | K9: Calado | M9: 7 | N9: 7 | O9: =+IF(M9=N9,"","E")
A10: Compuestos | D10: Temperatura | G10: Agitación-Oleaje | H10: Viento | J10: Visibilidad | K10: Calado | M10: 8 | N10: 8 | O10: =+IF(M10=N10,"","E")
A11: Compuestos | D11: Temperatura | G11: Agitación-Oleaje | H11: Viento | J11: Visibilidad | K11: Calado | M11: 9 | N11: 9 | O11: =+IF(M11=N11,"","E")
A12: Compuestos | D12: Temperatura | G12: Agitación-Oleaje | H12: Viento | J12: Visibilidad | K12: Calado | M12: 10 | N12: 10 | O12: =+IF(M12=N12,"","E")
A13: Compuestos | D13: Temperatura | G13: Agitación-Oleaje | H13: Viento | K13: Calado | M13: 11 | N13: 11 | O13: =+IF(M13=N13,"","E")
A14: Compuestos | D14: Temperatura | G14: Agitación-Oleaje | H14: Viento | K14: Calado | M14: 12 | N14: 12 | O14: =+IF(M14=N14,"","E")
A15: Compuestos | G15: Agitación-Oleaje | H15: Viento | K15: Calado | M15: 13 | N15: 13 | O15: =+IF(M15=N15,"","E")
A16: Compuestos | H16: Viento | K16: Calado | M16: 14 | N16: 14 | O16: =+IF(M16=N16,"","E")
A17: Compuestos | H17: Viento | K17: Calado | M17: 15 | N17: 15 | O17: =+IF(M17=N17,"","E")
A18: Compuestos | H18: Viento | M18: 16 | N18: 16 | O18: =+IF(M18=N18,"","E")
A19: Compuestos | H19: Viento | M19: 17 | N19: 17 | O19: =+IF(M19=N19,"","E")
A20: Compuestos | H20: Viento | M20: 18 | N20: 18 | O20: =+IF(M20=N20,"","E")
H21: Viento | M21: 19 | N21: 19 | O21: =+IF(M21=N21,"","E")
H22: Viento | M22: 20 | N22: 20 | O22: =+IF(M22=N22,"","E")
H23: Viento | M23: 21 | N23: 21 | O23: =+IF(M23=N23,"","E")
H24: Viento | M24: 22 | N24: 22 | O24: =+IF(M24=N24,"","E")
H25: Viento | M25: 23 | N25: 23 | O25: =+IF(M25=N25,"","E")
H26: Viento | M26: 24 | N26: 24 | O26: =+IF(M26=N26,"","E")
H27: Viento | M27: 25 | N27: 25 | O27: =+IF(M27=N27,"","E")
H28: Viento | M28: 26 | N28: 26 | O28: =+IF(M28=N28,"","E")
H29: Viento | M29: 27 | N29: 27 | O29: =+IF(M29=N29,"","E")
H30: Viento | M30: 28 | N30: 28 | O30: =+IF(M30=N30,"","E")
H31: Viento | M31: 29 | N31: 29 | O31: =+IF(M31=N31,"","E")
H32: Viento | M32: 30 | N32: 30 | O32: =+IF(M32=N32,"","E")
... H45: Viento | M45: 43 | N45: 43 | O45: =+IF(M45=N45,"","E")
M46: 44 | N46: 44 | O46: =+IF(M46=N46,"","E")
M47: 45 | N47: 45 | O47: =+IF(M47=N47,"","E")
M48: 46 | N48: 46 | O48: =+IF(M48=N48,"","E")
M49: 47 | N49: 47 | O49: =+IF(M49=N49,"","E")
M50: 48 | N50: 48 | O50: =+IF(M50=N50,"","E")
M51: 49 | N51: 49 | O51: =+IF(M51=N51,"","E")
M52: 50 | N52: 50 | O52: =+IF(M52=N52,"","E")
...

Sheet Agitación-Oleaje
A1: Pestaña | B1: No | C1: Tipo de impacto | D1: Modos de fallo / Modos de parada | E1: Variable | F1: Activo físico u Operacional | G1: Tipo activo/servicio | H1: =+_xlfn.CONCAT('ListRelacion impactos-indicador'!$H$1, " (",'ListRelacion impactos-indicador'!$G$2,")") -> Umbral General (m) | I1: Graneles Líquidos | J1: Graneles Sólidos | K1: Carga contenerizada | L1: Ro-ro y resto de mercancía general no contenerizada | M1: Pasajeros | N1: Pesquero | O1: Náutico-deportivo | P1: Puerto-ciudad
A2: {=_xlfn._xlws.FILTER(IF(B2:B176<>"","Agitación-Oleaje",""),B2:B176<>"")} -> Agitación-Oleaje | B2: {=_xlfn._xlws.FILTER('ListRelacion impactos-indicador'!A2:A182,(ISNUMBER(SEARCH("Agitación",'ListRelacion impactos-indicador'!$C$2:$C$182))+ISNUMBER(SEARCH("Exceso de Oleaje",'ListRelacion impactos-indicador'!$C$2:$C$182)))>0,"")} -> 1 | C2: {=_xlfn._xlws.FILTER('ListRelacion impactos-indicador'!B2:B182,(ISNUMBER(SEARCH("Agitación",'ListRelacion impactos-indicador'!$C$2:$C$182))+ISNUMBER(SEARCH("Exceso de Oleaje",'ListRelacion impactos-indicador'!$C$2:$C$182)))>0,"")} -> ELO | D2: {=_xlfn._xlws.FILTER('ListRelacion impactos-indicador'!C2:C182,(ISNUMBER(SEARCH("Agitación",'ListRelacion impactos-indicador'!$C$2:$C$182))+ISNUMBER(SEARCH("Exceso de Oleaje",'ListRelacion impactos-indicador'!$C$2:$C$182)))>0,"")} -> Exceso de Oleaje | E2: {=_xlfn._xlws.FILTER('ListRelacion impactos-indicador'!D2:D182,(ISNUMBER(SEARCH("Agitación",'ListRelacion impactos-indicador'!$C$2:$C$182))+ISNUMBER(SEARCH("Exceso de Oleaje",'ListRelacion impactos-indicador'!$C$2:$C$182)))>0,"")} -> Oleaje | F2: {=_xlfn._xlws.FILTER('ListRelacion impactos-indicador'!E2:E182,(ISNUMBER(SEARCH("Agitación",'ListRelacion impactos-indicador'!$C$2:$C$182))+ISNUMBER(SEARCH("Exceso de Oleaje",'ListRelacion impactos-indicador'!$C$2:$C$182)))>0,"")} -> Zona de fondeo y espera exterior | G2: {=_xlfn._xlws.FILTER('ListRelacion impactos-indicador'!F2:F182,(ISNUMBER(SEARCH("Agitación",'ListRelacion impactos-indicador'!$C$2:$C$182))+ISNUMBER(SEARCH("Exceso de Oleaje",'ListRelacion impactos-indicador'!$C$2:$C$182)))>0,"")} -> Activo físico | H2: {=_xlfn._xlws.FILTER(IF('ListRelacion impactos-indicador'!H2:H182="","",'ListRelacion impactos-indicador'!H2:H182),(ISNUMBER(SEARCH("Agitación",'ListRelacion impactos-indicador'!$C$2:$C$182))+ISNUMBER(SEARCH("Exceso de Oleaje",'ListRelacion impactos-indicador'!$C$2:$C$182)))>0,"")} -> 2.5 | I2: {=_xlfn._xlws.FILTER(IF('ListRelacion impactos-indicador'!I2:I182="","",'ListRelacion impactos-indicador'!I2:I182),(ISNUMBER(SEARCH("Agitación",'ListRelacion impactos-indicador'!$C$2:$C$182))+ISNUMBER(SEARCH("Exceso de Oleaje",'ListRelacion impactos-indicador'!$C$2:$C$182)))>0,"")} | J2: {=_xlfn._xlws.FILTER(IF('ListRelacion impactos-indicador'!J2:J182="","",'ListRelacion impactos-indicador'!J2:J182),(ISNUMBER(SEARCH("Agitación",'ListRelacion impactos-indicador'!$C$2:$C$182))+ISNUMBER(SEARCH("Exceso de Oleaje",'ListRelacion impactos-indicador'!$C$2:$C$182)))>0,"")} | K2: {=_xlfn._xlws.FILTER(IF('ListRelacion impactos-indicador'!K2:K182="","",'ListRelacion impactos-indicador'!K2:K182),(ISNUMBER(SEARCH("Agitación",'ListRelacion impactos-indicador'!$C$2:$C$182))+ISNUMBER(SEARCH("Exceso de Oleaje",'ListRelacion impactos-indicador'!$C$2:$C$182)))>0,"")} | L2: {=_xlfn._xlws.FILTER(IF('ListRelacion impactos-indicador'!L2:L182="","",'ListRelacion impactos-indicador'!L2:L182),(ISNUMBER(SEARCH("Agitación",'ListRelacion impactos-indicador'!$C$2:$C$182))+ISNUMBER(SEARCH("Exceso de Oleaje",'ListRelacion impactos-indicador'!$C$2:$C$182)))>0,"")} | M2: {=_xlfn._xlws.FILTER(IF('ListRelacion impactos-indicador'!M2:M182="","",'ListRelacion impactos-indicador'!M2:M182),(ISNUMBER(SEARCH("Agitación",'ListRelacion impactos-indicador'!$C$2:$C$182))+ISNUMBER(SEARCH("Exceso de Oleaje",'ListRelacion impactos-indicador'!$C$2:$C$182)))>0,"")} | N2: {=_xlfn._xlws.FILTER(IF('ListRelacion impactos-indicador'!N2:N182="","",'ListRelacion impactos-indicador'!N2:N182),(ISNUMBER(SEARCH("Agitación",'ListRelacion impactos-indicador'!$C$2:$C$182))+ISNUMBER(SEARCH("Exceso de Oleaje",'ListRelacion impactos-indicador'!$C$2:$C$182)))>0,"")} -> 5 | O2: {=_xlfn._xlws.FILTER(IF('ListRelacion impactos-indicador'!O2:O182="","",'ListRelacion impactos-indicador'!O2:O182),(ISNUMBER(SEARCH("Agitación",'ListRelacion impactos-indicador'!$C$2:$C$182))+ISNUMBER(SEARCH("Exceso de Oleaje",'ListRelacion impactos-indicador'!$C$2:$C$182)))>0,"")} -> 5 | P2: {=_xlfn._xlws.FILTER(IF('ListRelacion impactos-indicador'!P2:P182="","",'ListRelacion impactos-indicador'!P2:P182),(ISNUMBER(SEARCH("Agitación",'ListRelacion impactos-indicador'!$C$2:$C$182))+ISNUMBER(SEARCH("Exceso de Oleaje",'ListRelacion impactos-indicador'!$C$2:$C$182)))>0,"")}
A3: Agitación-Oleaje | B3: 3 | C3: ELO | D3: Exceso de Oleaje | E3: Oleaje | F3: Bocana | G3: Activo físico | H3: 2
A4: Agitación-Oleaje | B4: 7 | C4: ELO | D4: Exceso de Oleaje | E4: Oleaje | F4: Canal de acceso / navegación | G4: Activo físico | H4: 2.5
A5: Agitación-Oleaje | B5: 11 | C5: ELO | D5: Exceso de Oleaje | E5: Oleaje | F5: Dársenas (zona de permanencia) | G5: Activo físico | H5: 2
A6: Agitación-Oleaje | B6: 15 | C6: ELO | D6: Exceso de Oleaje | E6: Oleaje | F6: Dársenas (zona de maniobra y reviro) | G6: Activo físico | H6: 1
A7: Agitación-Oleaje | B7: 20 | C7: ELO | D7: Exceso de Oleaje | E7: Oleaje | F7: Servicio de prácticos | G7: Operacional (servicios) | H7: 1.5
A8: Agitación-Oleaje | B8: 23 | C8: ELO | D8: Exceso de Oleaje | E8: Oleaje | F8: Servicio de remolcadores | G8: Operacional (servicios) | H8: 1.5
A9: Agitación-Oleaje | B9: 26 | C9: ELO | D9: Exceso de Oleaje | E9: Oleaje | F9: Operaciones a flote (bunkering...) | G9: Operacional (servicios) | H9: 1.5
A10: Agitación-Oleaje | B10: 37 | C10: ELO | D10: Exceso de Oleaje | E10: Oleaje | F10: Muelle | G10: Activo físico | H10: 1.5 | I10: 1.5 | J10: 1.5 | L10: 0.3 | M10: 0.3 | N10: 0.4 | O10: 0.4
A11: Agitación-Oleaje | B11: 40 | C11: ELO | D11: Exceso de Oleaje | E11: Oleaje | F11: Pantalán | G11: Activo físico | H11: 1.5 | I11: 1.5 | J11: 1.5 | L11: 0.3 | M11: 0.3 | N11: 0.4 | O11: 0.4
A12: Agitación-Oleaje | B12: 43 | C12: ELO | D12: Exceso de Oleaje | E12: Oleaje | F12: Duque de alba | G12: Activo físico | H12: 1.5 | I12: 1.5 | J12: 1.5 | L12: 0.3 | M12: 0.3 | N12: 0.4 | O12: 0.4
A13: Agitación-Oleaje | B13: 45 | C13: ELO | D13: Exceso de Oleaje | E13: Oleaje | F13: Boya / monoboya | G13: Activo físico | H13: 1.5 | I13: 1.5 | J13: 1.5 | L13: 0.3 | M13: 0.3 | N13: 0.4 | O13: 0.4
A14: Agitación-Oleaje | B14: 48 | C14: ELO | D14: Exceso de Oleaje | E14: Oleaje | F14: Rampa Ro-Ro | G14: Activo físico | H14: 1.5 | I14: 1.5 | J14: 1.5 | L14: 0.3 | M14: 0.3 | N14: 0.4 | O14: 0.4

Sheet Asociados
A1: Pestaña | B1: No | C1: Tipo de impacto | D1: Modos de fallo / Modos de parada | E1: Variable | F1: Activo físico u Operacional | G1: Tipo activo/servicio | H1: =+_xlfn.CONCAT('ListRelacion impactos-indicador'!$H$1) -> Umbral General | I1: Graneles Líquidos | J1: Graneles Sólidos | K1: Carga contenerizada | L1: Ro-ro y resto de mercancía general no contenerizada | M1: Pasajeros | N1: Pesquero | O1: Náutico-deportivo | P1: Puerto-ciudad
A2: {=_xlfn._xlws.FILTER(IF(B2:B176<>"","Asociados",""),B2:B176<>"")} -> Asociados | B2: {=_xlfn._xlws.FILTER('ListRelacion impactos-indicador'!A2:A182,'ListRelacion impactos-indicador'!$D$2:$D$182="Asociado","")} -> 50 | C2: {=_xlfn._xlws.FILTER('ListRelacion impactos-indicador'!B2:B182,'ListRelacion impactos-indicador'!$D$2:$D$182="Asociado","")} -> ELO | D2: {=_xlfn._xlws.FILTER('ListRelacion impactos-indicador'!C2:C182,'ListRelacion impactos-indicador'!$D$2:$D$182="Asociado","")} -> Asociado a los EL de la obra de amarre y atraque (% de la perdida por parada) | E2: {=_xlfn._xlws.FILTER('ListRelacion impactos-indicador'!D2:D182,'ListRelacion impactos-indicador'!$D$2:$D$182="Asociado","")} -> Asociado | F2: {=_xlfn._xlws.FILTER('ListRelacion impactos-indicador'!E2:E182,'ListRelacion impactos-indicador'!$D$2:$D$182="Asociado","")} -> Servicio de amarradores | G2: {=_xlfn._xlws.FILTER('ListRelacion impactos-indicador'!F2:F182,'ListRelacion impactos-indicador'!$D$2:$D$182="Asociado","")} -> Operacional (servicios) | H2: {=_xlfn._xlws.FILTER(IF('ListRelacion impactos-indicador'!H2:H182="","",'ListRelacion impactos-indicador'!H2:H182),'ListRelacion impactos-indicador'!$D$2:$D$182="Asociado","")} | I2: {=_xlfn._xlws.FILTER(IF('ListRelacion impactos-indicador'!I2:I182="","",'ListRelacion impactos-indicador'!I2:I182),'ListRelacion impactos-indicador'!$D$2:$D$182="Asociado","")} | J2: {=_xlfn._xlws.FILTER(IF('ListRelacion impactos-indicador'!J2:J182="","",'ListRelacion impactos-indicador'!J2:J182),'ListRelacion impactos-indicador'!$D$2:$D$182="Asociado","")} | K2: {=_xlfn._xlws.FILTER(IF('ListRelacion impactos-indicador'!K2:K182="","",'ListRelacion impactos-indicador'!K2:K182),'ListRelacion impactos-indicador'!$D$2:$D$182="Asociado","")} | L2: {=_xlfn._xlws.FILTER(IF('ListRelacion impactos-indicador'!L2:L182="","",'ListRelacion impactos-indicador'!L2:L182),'ListRelacion impactos-indicador'!$D$2:$D$182="Asociado","")} | M2: {=_xlfn._xlws.FILTER(IF('ListRelacion impactos-indicador'!M2:M182="","",'ListRelacion impactos-indicador'!M2:M182),'ListRelacion impactos-indicador'!$D$2:$D$182="Asociado","")} | N2: {=_xlfn._xlws.FILTER(IF('ListRelacion impactos-indicador'!N2:N182="","",'ListRelacion impactos-indicador'!N2:N182),'ListRelacion impactos-indicador'!$D$2:$D$182="Asociado","")} | O2: {=_xlfn._xlws.FILTER(IF('ListRelacion impactos-indicador'!O2:O182="","",'ListRelacion impactos-indicador'!O2:O182),'ListRelacion impactos-indicador'!$D$2:$D$182="Asociado","")} | P2: {=_xlfn._xlws.FILTER(IF('ListRelacion impactos-indicador'!P2:P182="","",'ListRelacion impactos-indicador'!P2:P182),'ListRelacion impactos-indicador'!$D$2:$D$182="Asociado","")}
A3: Asociados | B3: 168 | C3: ELU | D3: Asociado a los EL de la obra de amarre y atraque (% del daño) | E3: Asociado | F3: Defensas y bolardos | G3: Activo físico
A4: Asociados | B4: 169 | C4: ELU | D4: Asociado a los EL de la obra de amarre y atraque (% del daño) | E4: Asociado | F4: Servicio de amarradores | G4: Operacional (servicios)

Sheet Calado
A1: Pestaña | B1: No | C1: Tipo de impacto | D1: Modos de fallo / Modos de parada | E1: Variable | F1: Activo físico u Operacional | G1: Tipo activo/servicio | H1: =+_xlfn.CONCAT('ListRelacion impactos-indicador'!$H$1, " (",'ListRelacion impactos-indicador'!$G$39,")") -> Umbral General (m) | I1: Graneles Líquidos | J1: Graneles Sólidos | K1: Carga contenerizada | L1: Ro-ro y resto de mercancía general no contenerizada | M1: Pasajeros | N1: Pesquero | O1: Náutico-deportivo | P1: Puerto-ciudad
A2: {=_xlfn._xlws.FILTER(IF(B2:B176<>"","Calado",""),B2:B176<>"")} -> Calado | B2: {=_xlfn._xlws.FILTER('ListRelacion impactos-indicador'!A2:A182,'ListRelacion impactos-indicador'!$C$2:$C$182="Falta de Calado","")} -> 38 | C2: {=_xlfn._xlws.FILTER('ListRelacion impactos-indicador'!B2:B182,'ListRelacion impactos-indicador'!$C$2:$C$182="Falta de Calado","")} -> ELO | D2: {=_xlfn._xlws.FILTER('ListRelacion impactos-indicador'!C2:C182,'ListRelacion impactos-indicador'!$C$2:$C$182="Falta de Calado","")} -> Falta de Calado | E2: {=_xlfn._xlws.FILTER('ListRelacion impactos-indicador'!D2:D182,'ListRelacion impactos-indicador'!$C$2:$C$182="Falta de Calado","")} -> Nivel del mar | F2: {=_xlfn._xlws.FILTER('ListRelacion impactos-indicador'!E2:E182,'ListRelacion impactos-indicador'!$C$2:$C$182="Falta de Calado","")} -> Muelle | G2: {=_xlfn._xlws.FILTER('ListRelacion impactos-indicador'!F2:F182,'ListRelacion impactos-indicador'!$C$2:$C$182="Falta de Calado","")} -> Activo físico | H2: {=_xlfn._xlws.FILTER(IF('ListRelacion impactos-indicador'!H2:H182="","",'ListRelacion impactos-indicador'!H2:H182),'ListRelacion impactos-indicador'!$C$2:$C$182="Falta de Calado","")} -> 1.05*Dc+0.75 | I2: {=_xlfn._xlws.FILTER(IF('ListRelacion impactos-indicador'!I2:I182="","",'ListRelacion impactos-indicador'!I2:I182),'ListRelacion impactos-indicador'!$C$2:$C$182="Falta de Calado","")} | J2: {=_xlfn._xlws.FILTER(IF('ListRelacion impactos-indicador'!J2:J182="","",'ListRelacion impactos-indicador'!J2:J182),'ListRelacion impactos-indicador'!$C$2:$C$182="Falta de Calado","")} | K2: {=_xlfn._xlws.FILTER(IF('ListRelacion impactos-indicador'!K2:K182="","",'ListRelacion impactos-indicador'!K2:K182),'ListRelacion impactos-indicador'!$C$2:$C$182="Falta de Calado","")} | L2: {=_xlfn._xlws.FILTER(IF('ListRelacion impactos-indicador'!L2:L182="","",'ListRelacion impactos-indicador'!L2:L182),'ListRelacion impactos-indicador'!$C$2:$C$182="Falta de Calado","")} | M2: {=_xlfn._xlws.FILTER(IF('ListRelacion impactos-indicador'!M2:M182="","",'ListRelacion impactos-indicador'!M2:M182),'ListRelacion impactos-indicador'!$C$2:$C$182="Falta de Calado","")} | N2: {=_xlfn._xlws.FILTER(IF('ListRelacion impactos-indicador'!N2:N182="","",'ListRelacion impactos-indicador'!N2:N182),'ListRelacion impactos-indicador'!$C$2:$C$182="Falta de Calado","")} | O2: {=_xlfn._xlws.FILTER(IF('ListRelacion impactos-indicador'!O2:O182="","",'ListRelacion impactos-indicador'!O2:O182),'ListRelacion impactos-indicador'!$C$2:$C$182="Falta de Calado","")} | P2: {=_xlfn._xlws.FILTER(IF('ListRelacion impactos-indicador'!P2:P182="","",'ListRelacion impactos-indicador'!P2:P182),'ListRelacion impactos-indicador'!$C$2:$C$182="Falta de Calado","")}
A3: Calado | B3: 41 | C3: ELO | D3: Falta de Calado | E3: Nivel del mar | F3: Pantalán | G3: Activo físico | H3: 1.05*Dc+0.75
A4: Calado | B4: 44 | C4: ELO | D4: Falta de Calado | E4: Nivel del mar | F4: Duque de alba | G4: Activo físico | H4: 1.05*Dc+0.75
A5: Calado | B5: 46 | C5: ELO | D5: Falta de Calado | E5: Nivel del mar | F5: Boya / monoboya | G5: Activo físico | H5: 1.05*Dc+0.75
A6: Calado | B6: 49 | C6: ELO | D6: Falta de Calado | E6: Nivel del mar | F6: Rampa Ro-Ro | G6: Activo físico | H6: 1.05*Dc+0.75
A7: Calado | B7: 94 | C7: ELS | D7: Falta de Calado | E7: Nivel del mar | F7: Zona de fondeo y espera exterior | G7: Activo físico | H7: 1.1*Dc+0.75
A8: Calado | B8: 95 | C8: ELS | D8: Falta de Calado | E8: Nivel del mar | F8: Bocana | G8: Activo físico | H8: 1.1*Dc+0.75
A9: Calado | B9: 96 | C9: ELS | D9: Falta de Calado | E9: Nivel del mar | F9: Canal de acceso/ navegación | G9: Activo físico | H9: 1.1*Dc+0.75
A10: Calado | B10: 97 | C10: ELS | D10: Falta de Calado | E10: Nivel del mar | F10: Dársenas (zona de permanencia) | G10: Activo físico | H10: 1.05*Dc+0.75
A11: Calado | B11: 98 | C11: ELS | D11: Falta de Calado | E11: Nivel del mar | F11: Dársenas (zona de maniobra y reviro) | G11: Activo físico | H11: 1.1*Dc+0.75
A12: Calado | B12: 152 | C12: ELU | D12: Falta de Calado | E12: Nivel del mar | F12: Zona de fondeo y espera exterior | G12: Activo físico | H12: 1.1*Dc+0.75
A13: Calado | B13: 153 | C13: ELU | D13: Falta de Calado | E13: Nivel del mar | F13: Bocana | G13: Activo físico | H13: 1.1*Dc+0.75
A14: Calado | B14: 154 | C14: ELU | D14: Falta de Calado | E14: Nivel del mar | F14: Canal de acceso/ navegación | G14: Activo físico | H14: 1.1*Dc+0.75
... A16: Calado | B16: 156 | C16: ELU | D16: Falta de Calado | E16: Nivel del mar | F16: Dársenas (zona de maniobra y reviro) | G16: Activo físico | H16: 1.1*Dc+0.75

Sheet Compuestos
A1: Pestaña | B1: No | C1: Tipo de impacto | D1: Modos de fallo / Modos de parada | E1: Variable | F1: Activo físico u Operacional | G1: Tipo activo/servicio | H1: =+_xlfn.CONCAT('ListRelacion impactos-indicador'!$H$1) -> Umbral General | I1: Graneles Líquidos | J1: Graneles Sólidos | K1: Carga contenerizada | L1: Ro-ro y resto de mercancía general no contenerizada | M1: Pasajeros | N1: Pesquero | O1: Náutico-deportivo | P1: Puerto-ciudad
A2: {=_xlfn._xlws.FILTER(IF(B2:B176<>"","Compuestos",""),B2:B176<>"")} -> Compuestos | B2: {=_xlfn._xlws.FILTER('ListRelacion impactos-indicador'!A2:A182,(ISNUMBER(SEARCH("Oleaje",'ListRelacion impactos-indicador'!$D$2:$D$182))*ISNUMBER(SEARCH("Nivel del mar",'ListRelacion impactos-indicador'!$D$2:$D$182)))+(ISNUMBER(SEARCH("Oleaje",'ListRelacion impactos-indicador'!$D$2:$D$182))*ISNUMBER(SEARCH("Corriente",'ListRelacion impactos-indicador'!$D$2:$D$182))*ISNUMBER(SEARCH("Velocidad del viento",'ListRelacion impactos-indicador'!$D$2:$D$182)))>0,"")} -> 29 | C2: {=_xlfn._xlws.FILTER('ListRelacion impactos-indicador'!B2:B182,(ISNUMBER(SEARCH("Oleaje",'ListRelacion impactos-indicador'!$D$2:$D$182))*ISNUMBER(SEARCH("Nivel del mar",'ListRelacion impactos-indicador'!$D$2:$D$182)))+(ISNUMBER(SEARCH("Oleaje",'ListRelacion impactos-indicador'!$D$2:$D$182))*ISNUMBER(SEARCH("Corriente",'ListRelacion impactos-indicador'!$D$2:$D$182))*ISNUMBER(SEARCH("Velocidad del viento",'ListRelacion impactos-indicador'!$D$2:$D$182)))>0,"")} -> ELO | D2: {=_xlfn._xlws.FILTER('ListRelacion impactos-indicador'!C2:C182,(ISNUMBER(SEARCH("Oleaje",'ListRelacion impactos-indicador'!$D$2:$D$182))*ISNUMBER(SEARCH("Nivel del mar",'ListRelacion impactos-indicador'!$D$2:$D$182)))+(ISNUMBER(SEARCH("Oleaje",'ListRelacion impactos-indicador'!$D$2:$D$182))*ISNUMBER(SEARCH("Corriente",'ListRelacion impactos-indicador'!$D$2:$D$182))*ISNUMBER(SEARCH("Velocidad del viento",'ListRelacion impactos-indicador'!$D$2:$D$182)))>0,"")} -> Carga hidráulica sobre las piezas de obras de abrigo (desplazamiento de las piezas del tronco, morro) | E2: {=_xlfn._xlws.FILTER('ListRelacion impactos-indicador'!D2:D182,(ISNUMBER(SEARCH("Oleaje",'ListRelacion impactos-indicador'!$D$2:$D$182))*ISNUMBER(SEARCH("Nivel del mar",'ListRelacion impactos-indicador'!$D$2:$D$182)))+(ISNUMBER(SEARCH("Oleaje",'ListRelacion impactos-indicador'!$D$2:$D$182))*ISNUMBER(SEARCH("Corriente",'ListRelacion impactos-indicador'!$D$2:$D$182))*ISNUMBER(SEARCH("Velocidad del viento",'ListRelacion impactos-indicador'!$D$2:$D$182)))>0,"")} -> Oleaje, Nivel del mar | F2: {=_xlfn._xlws.FILTER('ListRelacion impactos-indicador'!E2:E182,(ISNUMBER(SEARCH("Oleaje",'ListRelacion impactos-indicador'!$D$2:$D$182))*ISNUMBER(SEARCH("Nivel del mar",'ListRelacion impactos-indicador'!$D$2:$D$182)))+(ISNUMBER(SEARCH("Oleaje",'ListRelacion impactos-indicador'!$D$2:$D$182))*ISNUMBER(SEARCH("Corriente",'ListRelacion impactos-indicador'!$D$2:$D$182))*ISNUMBER(SEARCH("Velocidad del viento",'ListRelacion impactos-indicador'!$D$2:$D$182)))>0,"")} -> Dique en talud (con espaldón o sin espaldón) | G2: {=_xlfn._xlws.FILTER('ListRelacion impactos-indicador'!F2:F182,(ISNUMBER(SEARCH("Oleaje",'ListRelacion impactos-indicador'!$D$2:$D$182))*ISNUMBER(SEARCH("Nivel del mar",'ListRelacion impactos-indicador'!$D$2:$D$182)))+(ISNUMBER(SEARCH("Oleaje",'ListRelacion impactos-indicador'!$D$2:$D$182))*ISNUMBER(SEARCH("Corriente",'ListRelacion impactos-indicador'!$D$2:$D$182))*ISNUMBER(SEARCH("Velocidad del viento",'ListRelacion impactos-indicador'!$D$2:$D$182)))>0,"")} -> Activo físico | H2: {=_xlfn._xlws.FILTER(IF('ListRelacion impactos-indicador'!H2:H182="","",'ListRelacion impactos-indicador'!H2:H182),(ISNUMBER(SEARCH("Oleaje",'ListRelacion impactos-indicador'!$D$2:$D$182))*ISNUMBER(SEARCH("Nivel del mar",'ListRelacion impactos-indicador'!$D$2:$D$182)))+(ISNUMBER(SEARCH("Oleaje",'ListRelacion impactos-indicador'!$D$2:$D$182))*ISNUMBER(SEARCH("Corriente",'ListRelacion impactos-indicador'!$D$2:$D$182))*ISNUMBER(SEARCH("Velocidad del viento",'ListRelacion impactos-indicador'!$D$2:$D$182)))>0,"")} | I2: {=_xlfn._xlws.FILTER(IF('ListRelacion impactos-indicador'!I2:I182="","",'ListRelacion impactos-indicador'!I2:I182),(ISNUMBER(SEARCH("Oleaje",'ListRelacion impactos-indicador'!$D$2:$D$182))*ISNUMBER(SEARCH("Nivel del mar",'ListRelacion impactos-indicador'!$D$2:$D$182)))+(ISNUMBER(SEARCH("Oleaje",'ListRelacion impactos-indicador'!$D$2:$D$182))*ISNUMBER(SEARCH("Corriente",'ListRelacion impactos-indicador'!$D$2:$D$182))*ISNUMBER(SEARCH("Velocidad del viento",'ListRelacion impactos-indicador'!$D$2:$D$182)))>0,"")} | J2: {=_xlfn._xlws.FILTER(IF('ListRelacion impactos-indicador'!J2:J182="","",'ListRelacion impactos-indicador'!J2:J182),(ISNUMBER(SEARCH("Oleaje",'ListRelacion impactos-indicador'!$D$2:$D$182))*ISNUMBER(SEARCH("Nivel del mar",'ListRelacion impactos-indicador'!$D$2:$D$182)))+(ISNUMBER(SEARCH("Oleaje",'ListRelacion impactos-indicador'!$D$2:$D$182))*ISNUMBER(SEARCH("Corriente",'ListRelacion impactos-indicador'!$D$2:$D$182))*ISNUMBER(SEARCH("Velocidad del viento",'ListRelacion impactos-indicador'!$D$2:$D$182)))>0,"")} | K2: {=_xlfn._xlws.FILTER(IF('ListRelacion impactos-indicador'!K2:K182="","",'ListRelacion impactos-indicador'!K2:K182),(ISNUMBER(SEARCH("Oleaje",'ListRelacion impactos-indicador'!$D$2:$D$182))*ISNUMBER(SEARCH("Nivel del mar",'ListRelacion impactos-indicador'!$D$2:$D$182)))+(ISNUMBER(SEARCH("Oleaje",'ListRelacion impactos-indicador'!$D$2:$D$182))*ISNUMBER(SEARCH("Corriente",'ListRelacion impactos-indicador'!$D$2:$D$182))*ISNUMBER(SEARCH("Velocidad del viento",'ListRelacion impactos-indicador'!$D$2:$D$182)))>0,"")} | L2: {=_xlfn._xlws.FILTER(IF('ListRelacion impactos-indicador'!L2:L182="","",'ListRelacion impactos-indicador'!L2:L182),(ISNUMBER(SEARCH("Oleaje",'ListRelacion impactos-indicador'!$D$2:$D$182))*ISNUMBER(SEARCH("Nivel del mar",'ListRelacion impactos-indicador'!$D$2:$D$182)))+(ISNUMBER(SEARCH("Oleaje",'ListRelacion impactos-indicador'!$D$2:$D$182))*ISNUMBER(SEARCH("Corriente",'ListRelacion impactos-indicador'!$D$2:$D$182))*ISNUMBER(SEARCH("Velocidad del viento",'ListRelacion impactos-indicador'!$D$2:$D$182)))>0,"")} | M2: {=_xlfn._xlws.FILTER(IF('ListRelacion impactos-indicador'!M2:M182="","",'ListRelacion impactos-indicador'!M2:M182),(ISNUMBER(SEARCH("Oleaje",'ListRelacion impactos-indicador'!$D$2:$D$182))*ISNUMBER(SEARCH("Nivel del mar",'ListRelacion impactos-indicador'!$D$2:$D$182)))+(ISNUMBER(SEARCH("Oleaje",'ListRelacion impactos-indicador'!$D$2:$D$182))*ISNUMBER(SEARCH("Corriente",'ListRelacion impactos-indicador'!$D$2:$D$182))*ISNUMBER(SEARCH("Velocidad del viento",'ListRelacion impactos-indicador'!$D$2:$D$182)))>0,"")} | N2: {=_xlfn._xlws.FILTER(IF('ListRelacion impactos-indicador'!N2:N182="","",'ListRelacion impactos-indicador'!N2:N182),(ISNUMBER(SEARCH("Oleaje",'ListRelacion impactos-indicador'!$D$2:$D$182))*ISNUMBER(SEARCH("Nivel del mar",'ListRelacion impactos-indicador'!$D$2:$D$182)))+(ISNUMBER(SEARCH("Oleaje",'ListRelacion impactos-indicador'!$D$2:$D$182))*ISNUMBER(SEARCH("Corriente",'ListRelacion impactos-indicador'!$D$2:$D$182))*ISNUMBER(SEARCH("Velocidad del viento",'ListRelacion impactos-indicador'!$D$2:$D$182)))>0,"")} | O2: {=_xlfn._xlws.FILTER(IF('ListRelacion impactos-indicador'!O2:O182="","",'ListRelacion impactos-indicador'!O2:O182),(ISNUMBER(SEARCH("Oleaje",'ListRelacion impactos-indicador'!$D$2:$D$182))*ISNUMBER(SEARCH("Nivel del mar",'ListRelacion impactos-indicador'!$D$2:$D$182)))+(ISNUMBER(SEARCH("Oleaje",'ListRelacion impactos-indicador'!$D$2:$D$182))*ISNUMBER(SEARCH("Corriente",'ListRelacion impactos-indicador'!$D$2:$D$182))*ISNUMBER(SEARCH("Velocidad del viento",'ListRelacion impactos-indicador'!$D$2:$D$182)))>0,"")} | P2: {=_xlfn._xlws.FILTER(IF('ListRelacion impactos-indicador'!P2:P182="","",'ListRelacion impactos-indicador'!P2:P182),(ISNUMBER(SEARCH("Oleaje",'ListRelacion impactos-indicador'!$D$2:$D$182))*ISNUMBER(SEARCH("Nivel del mar",'ListRelacion impactos-indicador'!$D$2:$D$182)))+(ISNUMBER(SEARCH("Oleaje",'ListRelacion impactos-indicador'!$D$2:$D$182))*ISNUMBER(SEARCH("Corriente",'ListRelacion impactos-indicador'!$D$2:$D$182))*ISNUMBER(SEARCH("Velocidad del viento",'ListRelacion impactos-indicador'!$D$2:$D$182)))>0,"")}
A3: Compuestos | B3: 30 | C3: ELO | D3: Carga hidráulica sobre las piezas de obras de abrigo (erosión berma de pie) | E3: Oleaje, Nivel del mar | F3: Dique en talud (con espaldón o sin espaldón) | G3: Activo físico
A4: Compuestos | B4: 31 | C4: ELO | D4: Carga hidráulica sobre las piezas de obras de abrigo (desplazamiento o vuelco del espaldón) | E4: Oleaje, Nivel del mar | F4: Dique en talud (con espaldón o sin espaldón) | G4: Activo físico
A5: Compuestos | B5: 33 | C5: ELO | D5: Carga hidráulica sobre las piezas de obras de abrigo (desplazamiento de las piezas del tronco, morro o berma) | E5: Oleaje, Nivel del mar | F5: Dique vertical | G5: Activo físico
A6: Compuestos | B6: 34 | C6: ELO | D6: Carga hidráulica sobre las piezas de obras de abrigo (erosión de la banqueta) | E6: Oleaje, Nivel del mar | F6: Dique vertical | G6: Activo físico
A7: Compuestos | B7: 35 | C7: ELO | D7: Carga hidráulica sobre las piezas de obras de abrigo (desplazamiento o vuelco del espaldón) | E7: Oleaje, Nivel del mar | F7: Dique vertical | G7: Activo físico
A8: Compuestos | B8: 99 | C8: ELS | D8: Deterioro de la señalización/balizamiento | E8: Oleaje, Corriente, Nivel medio del mar, Velocidad del viento | F8: Señalización y balizado | G8: Activo físico
A9: Compuestos | B9: 157 | C9: ELU | D9: Fallo de la señalización/balizamiento | E9: Oleaje, Corriente, Nivel medio del mar, Velocidad del viento | F9: Señalización y balizado | G9: Activo físico
A10: Compuestos | B10: 158 | C10: ELU | D10: Carga hidráulica sobre las piezas de obras de abrigo (desplazamiento de las piezas del tronco, morro) | E10: Oleaje, Nivel del mar | F10: Dique en talud (con espaldón o sin espaldón) | G10: Activo físico
A11: Compuestos | B11: 159 | C11: ELU | D11: Carga hidráulica sobre las piezas de obras de abrigo (erosión berma de pie) | E11: Oleaje, Nivel del mar | F11: Dique en talud (con espaldón o sin espaldón) | G11: Activo físico
A12: Compuestos | B12: 160 | C12: ELU | D12: Carga hidráulica sobre las piezas de obras de abrigo (desplazamiento o vuelco del espaldón) | E12: Oleaje, Nivel del mar | F12: Dique en talud (con espaldón o sin espaldón) | G12: Activo físico
A13: Compuestos | B13: 161 | C13: ELU | D13: Carga hidráulica sobre las piezas de obras de abrigo (desplazamiento de las piezas del tronco, morro o berma) | E13: Oleaje, Nivel del mar | F13: Dique vertical | G13: Activo físico
A14: Compuestos | B14: 162 | C14: ELU | D14: Carga hidráulica sobre las piezas de obras de abrigo (erosión de la banqueta) | E14: Oleaje, Nivel del mar | F14: Dique vertical | G14: Activo físico
... A19: Compuestos | B19: 167 | C19: ELU | D19: Carga hidráulica sobre las obras de amarre | E19: Oleaje, Nivel del mar | F19: Boya / monoboya | G19: Activo físico
A25: =IF(B25<>"","Compuestos","")

Sheet Corriente
A1: Pestaña | B1: No | C1: Tipo de impacto | D1: Modos de fallo / Modos de parada | E1: Variable | F1: Activo físico u Operacional | G1: Tipo activo/servicio | H1: =+_xlfn.CONCAT('ListRelacion impactos-indicador'!$H$1, " (",'ListRelacion impactos-indicador'!$G$6,")") -> Umbral General (m/s) | I1: Graneles Líquidos | J1: Graneles Sólidos | K1: Carga contenerizada | L1: Ro-ro y resto de mercancía general no contenerizada | M1: Pasajeros | N1: Pesquero | O1: Náutico-deportivo | P1: Puerto-ciudad
A2: {=_xlfn._xlws.FILTER(IF(B2:B176<>"","Corriente",""),B2:B176<>"")} -> Corriente | B2: {=_xlfn._xlws.FILTER('ListRelacion impactos-indicador'!A2:A182,'ListRelacion impactos-indicador'!$D$2:$D$182="Corriente","")} -> 5 | C2: {=_xlfn._xlws.FILTER('ListRelacion impactos-indicador'!B2:B182,'ListRelacion impactos-indicador'!$D$2:$D$182="Corriente","")} -> ELO | D2: {=_xlfn._xlws.FILTER('ListRelacion impactos-indicador'!C2:C182,'ListRelacion impactos-indicador'!$D$2:$D$182="Corriente","")} -> Exceso de Corriente | E2: {=_xlfn._xlws.FILTER('ListRelacion impactos-indicador'!D2:D182,'ListRelacion impactos-indicador'!$D$2:$D$182="Corriente","")} -> Corriente | F2: {=_xlfn._xlws.FILTER('ListRelacion impactos-indicador'!E2:E182,'ListRelacion impactos-indicador'!$D$2:$D$182="Corriente","")} -> Bocana | G2: {=_xlfn._xlws.FILTER('ListRelacion impactos-indicador'!F2:F182,'ListRelacion impactos-indicador'!$D$2:$D$182="Corriente","")} -> Activo físico | H2: {=_xlfn._xlws.FILTER(IF('ListRelacion impactos-indicador'!H2:H182="","",'ListRelacion impactos-indicador'!H2:H182),'ListRelacion impactos-indicador'!$D$2:$D$182="Corriente","")} -> 0.5 | I2: {=_xlfn._xlws.FILTER(IF('ListRelacion impactos-indicador'!I2:I182="","",'ListRelacion impactos-indicador'!I2:I182),'ListRelacion impactos-indicador'!$D$2:$D$182="Corriente","")} | J2: {=_xlfn._xlws.FILTER(IF('ListRelacion impactos-indicador'!J2:J182="","",'ListRelacion impactos-indicador'!J2:J182),'ListRelacion impactos-indicador'!$D$2:$D$182="Corriente","")} | K2: {=_xlfn._xlws.FILTER(IF('ListRelacion impactos-indicador'!K2:K182="","",'ListRelacion impactos-indicador'!K2:K182),'ListRelacion impactos-indicador'!$D$2:$D$182="Corriente","")} | L2: {=_xlfn._xlws.FILTER(IF('ListRelacion impactos-indicador'!L2:L182="","",'ListRelacion impactos-indicador'!L2:L182),'ListRelacion impactos-indicador'!$D$2:$D$182="Corriente","")} | M2: {=_xlfn._xlws.FILTER(IF('ListRelacion impactos-indicador'!M2:M182="","",'ListRelacion impactos-indicador'!M2:M182),'ListRelacion impactos-indicador'!$D$2:$D$182="Corriente","")} | N2: {=_xlfn._xlws.FILTER(IF('ListRelacion impactos-indicador'!N2:N182="","",'ListRelacion impactos-indicador'!N2:N182),'ListRelacion impactos-indicador'!$D$2:$D$182="Corriente","")} -> 2 | O2: {=_xlfn._xlws.FILTER(IF('ListRelacion impactos-indicador'!O2:O182="","",'ListRelacion impactos-indicador'!O2:O182),'ListRelacion impactos-indicador'!$D$2:$D$182="Corriente","")} -> 2 | P2: {=_xlfn._xlws.FILTER(IF('ListRelacion impactos-indicador'!P2:P182="","",'ListRelacion impactos-indicador'!P2:P182),'ListRelacion impactos-indicador'!$D$2:$D$182="Corriente","")}
A3: Corriente | B3: 9 | C3: ELO | D3: Exceso de Corriente | E3: Corriente | F3: Canal de acceso / navegación | G3: Activo físico | H3: 2
A4: Corriente | B4: 13 | C4: ELO | D4: Exceso de Corriente | E4: Corriente | F4: Dársenas (zona de permanencia) | G4: Activo físico | H4: 0.5
A5: Corriente | B5: 17 | C5: ELO | D5: Exceso de Corriente | E5: Corriente | F5: Dársenas (zona de maniobra y reviro) | G5: Activo físico | H5: 0.5

Sheet Francobordo
A1: Pestaña | B1: No | C1: Tipo de impacto | D1: Modos de fallo / Modos de parada | E1: Variable | F1: Activo físico u Operacional | G1: Tipo activo/servicio | H1: =+_xlfn.CONCAT('ListRelacion impactos-indicador'!$H$1, " (",'ListRelacion impactos-indicador'!$G$37,")") -> Umbral General (m) | I1: Graneles Líquidos | J1: Graneles Sólidos | K1: Carga contenerizada | L1: Ro-ro y resto de mercancía general no contenerizada | M1: Pasajeros | N1: Pesquero | O1: Náutico-deportivo | P1: Puerto-ciudad
A2: {=_xlfn._xlws.FILTER(IF(B2:B176<>"","Francobordo",""),B2:B176<>"")} -> Francobordo | B2: {=_xlfn._xlws.FILTER('ListRelacion impactos-indicador'!A2:A182,'ListRelacion impactos-indicador'!$C$2:$C$182="Falta de francobordo","")} -> 36 | C2: {=_xlfn._xlws.FILTER('ListRelacion impactos-indicador'!B2:B182,'ListRelacion impactos-indicador'!$C$2:$C$182="Falta de francobordo","")} -> ELO | D2: {=_xlfn._xlws.FILTER('ListRelacion impactos-indicador'!C2:C182,'ListRelacion impactos-indicador'!$C$2:$C$182="Falta de francobordo","")} -> Falta de francobordo | E2: {=_xlfn._xlws.FILTER('ListRelacion impactos-indicador'!D2:D182,'ListRelacion impactos-indicador'!$C$2:$C$182="Falta de francobordo","")} -> Nivel del mar | F2: {=_xlfn._xlws.FILTER('ListRelacion impactos-indicador'!E2:E182,'ListRelacion impactos-indicador'!$C$2:$C$182="Falta de francobordo","")} -> Muelle | G2: {=_xlfn._xlws.FILTER('ListRelacion impactos-indicador'!F2:F182,'ListRelacion impactos-indicador'!$C$2:$C$182="Falta de francobordo","")} -> Activo físico | H2: {=_xlfn._xlws.FILTER(IF('ListRelacion impactos-indicador'!H2:H182="","",'ListRelacion impactos-indicador'!H2:H182),'ListRelacion impactos-indicador'!$C$2:$C$182="Falta de francobordo","")} -> 0.5 | I2: {=_xlfn._xlws.FILTER(IF('ListRelacion impactos-indicador'!I2:I182="","",'ListRelacion impactos-indicador'!I2:I182),'ListRelacion impactos-indicador'!$C$2:$C$182="Falta de francobordo","")} | J2: {=_xlfn._xlws.FILTER(IF('ListRelacion impactos-indicador'!J2:J182="","",'ListRelacion impactos-indicador'!J2:J182),'ListRelacion impactos-indicador'!$C$2:$C$182="Falta de francobordo","")} | K2: {=_xlfn._xlws.FILTER(IF('ListRelacion impactos-indicador'!K2:K182="","",'ListRelacion impactos-indicador'!K2:K182),'ListRelacion impactos-indicador'!$C$2:$C$182="Falta de francobordo","")} | L2: {=_xlfn._xlws.FILTER(IF('ListRelacion impactos-indicador'!L2:L182="","",'ListRelacion impactos-indicador'!L2:L182),'ListRelacion impactos-indicador'!$C$2:$C$182="Falta de francobordo","")} | M2: {=_xlfn._xlws.FILTER(IF('ListRelacion impactos-indicador'!M2:M182="","",'ListRelacion impactos-indicador'!M2:M182),'ListRelacion impactos-indicador'!$C$2:$C$182="Falta de francobordo","")} | N2: {=_xlfn._xlws.FILTER(IF('ListRelacion impactos-indicador'!N2:N182="","",'ListRelacion impactos-indicador'!N2:N182),'ListRelacion impactos-indicador'!$C$2:$C$182="Falta de francobordo","")} | O2: {=_xlfn._xlws.FILTER(IF('ListRelacion impactos-indicador'!O2:O182="","",'ListRelacion impactos-indicador'!O2:O182),'ListRelacion impactos-indicador'!$C$2:$C$182="Falta de francobordo","")} | P2: {=_xlfn._xlws.FILTER(IF('ListRelacion impactos-indicador'!P2:P182="","",'ListRelacion impactos-indicador'!P2:P182),'ListRelacion impactos-indicador'!$C$2:$C$182="Falta de francobordo","")}
A3: Francobordo | B3: 39 | C3: ELO | D3: Falta de francobordo | E3: Nivel del mar | F3: Pantalán | G3: Activo físico | H3: 0.5
A4: Francobordo | B4: 42 | C4: ELO | D4: Falta de francobordo | E4: Nivel del mar | F4: Duque de alba | G4: Activo físico | H4: 0.5
A5: Francobordo | B5: 47 | C5: ELO | D5: Falta de francobordo | E5: Nivel del mar | F5: Rampa Ro-Ro | G5: Activo físico | H5: 0.5

Sheet Inundación costera
A1: Pestaña | B1: No | C1: Tipo de impacto | D1: Modos de fallo / Modos de parada | E1: Variable | F1: Activo físico u Operacional | G1: Tipo activo/servicio | H1: =+_xlfn.CONCAT('ListRelacion impactos-indicador'!$H$1, " (",'ListRelacion impactos-indicador'!$G$52,")") -> Umbral General () | I1: Graneles Líquidos | J1: Graneles Sólidos | K1: Carga contenerizada | L1: Ro-ro y resto de mercancía general no contenerizada | M1: Pasajeros | N1: Pesquero | O1: Náutico-deportivo | P1: Puerto-ciudad
A2: {=_xlfn._xlws.FILTER(IF(B2:B176<>"","Inundación",""),B2:B176<>"")} -> Inundación | B2: {=_xlfn._xlws.FILTER('ListRelacion impactos-indicador'!A2:A182,'ListRelacion impactos-indicador'!$D$2:$D$182="Inundación costera","")} -> 51 | C2: {=_xlfn._xlws.FILTER('ListRelacion impactos-indicador'!B2:B182,'ListRelacion impactos-indicador'!$D$2:$D$182="Inundación costera","")} -> ELO | D2: {=_xlfn._xlws.FILTER('ListRelacion impactos-indicador'!C2:C182,'ListRelacion impactos-indicador'!$D$2:$D$182="Inundación costera","")} -> Inundación costera | E2: {=_xlfn._xlws.FILTER('ListRelacion impactos-indicador'!D2:D182,'ListRelacion impactos-indicador'!$D$2:$D$182="Inundación costera","")} -> Inundación costera | F2: {=_xlfn._xlws.FILTER('ListRelacion impactos-indicador'!E2:E182,'ListRelacion impactos-indicador'!$D$2:$D$182="Inundación costera","")} -> Superficies | G2: {=_xlfn._xlws.FILTER('ListRelacion impactos-indicador'!F2:F182,'ListRelacion impactos-indicador'!$D$2:$D$182="Inundación costera","")} -> Activo físico | H2: {=_xlfn._xlws.FILTER(IF('ListRelacion impactos-indicador'!H2:H182="","",'ListRelacion impactos-indicador'!H2:H182),'ListRelacion impactos-indicador'!$D$2:$D$182="Inundación costera","")} | I2: {=_xlfn._xlws.FILTER(IF('ListRelacion impactos-indicador'!I2:I182="","",'ListRelacion impactos-indicador'!I2:I182),'ListRelacion impactos-indicador'!$D$2:$D$182="Inundación costera","")} | J2: {=_xlfn._xlws.FILTER(IF('ListRelacion impactos-indicador'!J2:J182="","",'ListRelacion impactos-indicador'!J2:J182),'ListRelacion impactos-indicador'!$D$2:$D$182="Inundación costera","")} | K2: {=_xlfn._xlws.FILTER(IF('ListRelacion impactos-indicador'!K2:K182="","",'ListRelacion impactos-indicador'!K2:K182),'ListRelacion impactos-indicador'!$D$2:$D$182="Inundación costera","")} | L2: {=_xlfn._xlws.FILTER(IF('ListRelacion impactos-indicador'!L2:L182="","",'ListRelacion impactos-indicador'!L2:L182),'ListRelacion impactos-indicador'!$D$2:$D$182="Inundación costera","")} | M2: {=_xlfn._xlws.FILTER(IF('ListRelacion impactos-indicador'!M2:M182="","",'ListRelacion impactos-indicador'!M2:M182),'ListRelacion impactos-indicador'!$D$2:$D$182="Inundación costera","")} | N2: {=_xlfn._xlws.FILTER(IF('ListRelacion impactos-indicador'!N2:N182="","",'ListRelacion impactos-indicador'!N2:N182),'ListRelacion impactos-indicador'!$D$2:$D$182="Inundación costera","")} | O2: {=_xlfn._xlws.FILTER(IF('ListRelacion impactos-indicador'!O2:O182="","",'ListRelacion impactos-indicador'!O2:O182),'ListRelacion impactos-indicador'!$D$2:$D$182="Inundación costera","")} | P2: {=_xlfn._xlws.FILTER(IF('ListRelacion impactos-indicador'!P2:P182="","",'ListRelacion impactos-indicador'!P2:P182),'ListRelacion impactos-indicador'!$D$2:$D$182="Inundación costera","")}
A3: Inundación | B3: 52 | C3: ELO | D3: Inundación costera | E3: Inundación costera | F3: Pavimentos | G3: Activo físico
A4: Inundación | B4: 53 | C4: ELO | D4: Inundación | E4: Inundación costera | F4: Electricidad | G4: Activo físico
A5: Inundación | B5: 54 | C5: ELO | D5: Inundación costera | E5: Inundación costera | F5: Alumbrado | G5: Activo físico
A6: Inundación | B6: 55 | C6: ELO | D6: Inundación | E6: Inundación costera | F6: Suministro de agua | G6: Activo físico
A7: Inundación | B7: 57 | C7: ELO | D7: Inundación | E7: Inundación costera | F7: Telecomunicaciones y datos | G7: Activo físico
A8: Inundación | B8: 58 | C8: ELO | D8: Inundación costera | E8: Inundación costera | F8: Accesos ferroviarios y terminales ferroportuarias | G8: Activo físico
A9: Inundación | B9: 59 | C9: ELO | D9: Inundación costera | E9: Inundación costera | F9: Accesos viarios | G9: Activo físico
A10: Inundación | B10: 60 | C10: ELO | D10: Inundación costera | E10: Inundación costera | F10: Edificios de servicios generales (Oficinas, Aduanas, PIF, Control de accesos, etc.) | G10: Activo físico
A11: Inundación | B11: 62 | C11: ELO | D11: Inundación costera | E11: Inundación costera | F11: Manipulación de mercancía | G11: Operacional (servicios)
A12: Inundación | B12: 68 | C12: ELO | D12: Inundación costera | E12: Inundación costera | F12: Zonas de Actividad Logística | G12: Activo físico
A13: Inundación | B13: 70 | C13: ELO | D13: Inundación | E13: Inundación costera | F13: Astilleros, diques secos, varaderos | G13: Activo físico
A14: Inundación | B14: 71 | C14: ELO | D14: Inundación | E14: Inundación costera | F14: Tanques de almacenamiento | G14: Activo físico
... A53: Inundación | B53: 149 | C53: ELS | D53: Inundación | E53: Inundación costera | F53: Equipamientos culturales o deportivos | G53: Activo físico

Sheet Precipitación
A1: Pestaña | B1: No | C1: Tipo de impacto | D1: Modos de fallo / Modos de parada | E1: Variable | F1: Activo físico u Operacional | G1: Tipo activo/servicio | H1: =+_xlfn.CONCAT('ListRelacion impactos-indicador'!$H$1, " (",'ListRelacion impactos-indicador'!$G$64,")") -> Umbral General (mm) | I1: Graneles Líquidos | J1: Graneles Sólidos | K1: Carga contenerizada | L1: Ro-ro y resto de mercancía general no contenerizada | M1: Pasajeros | N1: Pesquero | O1: Náutico-deportivo | P1: Puerto-ciudad
